Workbook

Sheet Instructions
B2: AI Infrastructure TCO Calculator
B3: By Julien Simon | AI Operating Partner, Fortino Capital
B4: Last uodate February 18, 2026
B6: How to use this calculator
B8: 1. Go to the 'Your Inputs' tab and fill in all yellow-highlighted cells with your specific values.
B9: 2. Blue text = your inputs. Black text = calculated formulas. Do not edit black-text cells.
B10: 3. Select models from the built-in DROPDOWNS in Provider 1–3. Prices auto-populate from the Model Library.
B11: 4. Provider 4 is for CUSTOM providers (e.g., Together.ai, Fireworks, Groq). Enter your own name and pricing.
B12: 5. To override auto-populated prices, simply type over the formula in any price cell.
B13: 6. The 'API Costs' tab compares annual costs across all 4 providers.
B14: 7. The 'Self-Hosted GPU' tab calculates costs for running open-weights models on cloud GPUs.
B15: 8. The 'Local / Edge' tab calculates costs for on-premises or edge deployment.
... B24: • 50 Questions to Ask Before Buying AI Software (PDF)

Sheet Your Inputs
B2: Your Inputs
B3: Fill in all yellow cells. Dropdowns auto-populate pricing from the Model Library.
B5: USAGE PARAMETERS
B6: Average tokens per request (input) | C6: 500 | D6: Typical prompt length in tokens
B7: Average tokens per request (output) | C7: 200 | D7: Typical response length in tokens
B8: Requests per day | C8: 10000 | D8: Total API/inference calls per day
B9: Days of operation per year | C9: 365 | D9: Business days or 365 for always-on
B11: CALCULATED USAGE
B12: Input tokens per day | C12: =C6*C8 -> 5000000 | D12: input tokens/request × requests/day
B13: Output tokens per day | C13: =C7*C8 -> 2000000 | D13: output tokens/request × requests/day
B14: Total tokens per day | C14: =C12+C13 -> 7000000
B15: Input tokens per year (millions) | C15: =C12*C9/1000000 -> 1825
B16: Output tokens per year (millions) | C16: =C13*C9/1000000 -> 730
B18: API PRICING (per 1M tokens) — Select models from dropdown ▼
B19: Provider 1: model | C19: Claude Sonnet 4.6 | D19: Select from dropdown ▼ or type a custom model name
B20: Provider 1: input price / 1M tokens ($) | C20: =IFERROR(VLOOKUP(C19,'Model Library'!$A$2:$D$27,3,FALSE),0) -> 3 | D20: Auto-populated from Model Library. Type over to customize.
B21: Provider 1: output price / 1M tokens ($) | C21: =IFERROR(VLOOKUP(C19,'Model Library'!$A$2:$D$27,4,FALSE),0) -> 15 | D21: Auto-populated from Model Library. Type over to customize.
B22: Provider 2: model | C22: GPT-5 | D22: Select from dropdown ▼ or type a custom model name
B23: Provider 2: input price / 1M tokens ($) | C23: =IFERROR(VLOOKUP(C22,'Model Library'!$A$2:$D$27,3,FALSE),0) -> 1.25 | D23: Auto-populated from Model Library. Type over to customize.
B24: Provider 2: output price / 1M tokens ($) | C24: =IFERROR(VLOOKUP(C22,'Model Library'!$A$2:$D$27,4,FALSE),0) -> 10 | D24: Auto-populated from Model Library. Type over to customize.
B25: Provider 3: model | C25: Gemini 2.5 Flash | D25: Select from dropdown ▼ or type a custom model name
B26: Provider 3: input price / 1M tokens ($) | C26: =IFERROR(VLOOKUP(C25,'Model Library'!$A$2:$D$27,3,FALSE),0) -> 0.15 | D26: Auto-populated from Model Library. Type over to customize.
B27: Provider 3: output price / 1M tokens ($) | C27: =IFERROR(VLOOKUP(C25,'Model Library'!$A$2:$D$27,4,FALSE),0) -> 0.6 | D27: Auto-populated from Model Library. Type over to customize.
B28: Provider 4: model (custom) | C28: Custom Provider | D28: Type any name (e.g., Together.ai Llama 3.2 70B, Groq, Fireworks)
B29: Provider 4: input price / 1M tokens ($) | C29: 0.5 | D29: Enter your provider's input token price per 1M tokens
B30: Provider 4: output price / 1M tokens ($) | C30: 1.5 | D30: Enter your provider's output token price per 1M tokens
B32: SELF-HOSTED GPU PARAMETERS
B33: GPU type | C33: H100 | D33: H100, H200, or B200
B34: GPU cost per hour ($) | C34: 2.5 | D34: Cloud rental rate. H100: $1.49–$3.90, H200: $2.50–$4.31
B35: Number of GPUs needed | C35: 1 | D35: For 7B model: 1 GPU. For 70B model: 2–4 GPUs
B36: GPU utilization (%) | C36: 70 | D36: Realistic avg utilization (60–80% typical)
B37: Hours per day running | C37: 24 | D37: 24 for always-on, or business hours only
B38: Inference throughput (tokens/sec/GPU) | C38: 2300 | D38: vLLM on H100: ~2300 tok/s for 8B model
B39: ML engineer salary (annual, $) | C39: 180000 | D39: Fully loaded cost for infrastructure management
B40: ML engineer % time on this project | C40: 25 | D40: Percentage of their time dedicated to this
B41: Setup & migration cost (one-time, $) | C41: 15000 | D41: Initial deployment, testing, optimization
B43: LOCAL / EDGE PARAMETERS
B44: Hardware type | C44: RTX 5090 | D44: GPU/NPU for local inference
B45: Hardware purchase cost ($) | C45: 1999 | D45: One-time capital expenditure. RTX 5090 MSRP: $1,999
B46: Number of devices | C46: 1 | D46: How many inference devices
...

Sheet API Costs
B2: LLM API Cost Analysis
B3: Costs for 4 API providers based on your usage inputs
B4: Metric | C4: ='Your Inputs'!C19 -> Claude Sonnet 4.6 | D4: ='Your Inputs'!C22 -> GPT-5 | E4: ='Your Inputs'!C25 -> Gemini 2.5 Flash | F4: ='Your Inputs'!C28 -> Custom Provider
B5: Input price / 1M tokens | C5: ='Your Inputs'!C20 -> 3 | D5: ='Your Inputs'!C23 -> 1.25 | E5: ='Your Inputs'!C26 -> 0.15 | F5: ='Your Inputs'!C29 -> 0.5
B6: Output price / 1M tokens | C6: ='Your Inputs'!C21 -> 15 | D6: ='Your Inputs'!C24 -> 10 | E6: ='Your Inputs'!C27 -> 0.6 | F6: ='Your Inputs'!C30 -> 1.5
B7: Input tokens/year (M) | C7: ='Your Inputs'!C15 -> 1825 | D7: ='Your Inputs'!C15 -> 1825 | E7: ='Your Inputs'!C15 -> 1825 | F7: ='Your Inputs'!C15 -> 1825
B8: Output tokens/year (M) | C8: ='Your Inputs'!C16 -> 730 | D8: ='Your Inputs'!C16 -> 730 | E8: ='Your Inputs'!C16 -> 730 | F8: ='Your Inputs'!C16 -> 730
B9: Annual input cost ($) | C9: =C5*C7 -> 5475 | D9: =D5*D7 -> 2281.25 | E9: =E5*E7 -> 273.75 | F9: =F5*F7 -> 912.5
B10: Annual output cost ($) | C10: =C6*C8 -> 10950 | D10: =D6*D8 -> 7300 | E10: =E6*E8 -> 438 | F10: =F6*F8 -> 1095
B11: Total annual cost ($) | C11: =C9+C10 -> 16425 | D11: =D9+D10 -> 9581.25 | E11: =E9+E10 -> 711.75 | F11: =F9+F10 -> 2007.5
B12: Monthly cost ($) | C12: =C11/12 -> 1368.75 | D12: =D11/12 -> 798.4375 | E12: =E11/12 -> 59.3125 | F12: =F11/12 -> 167.29167
B13: Cost per 1K requests ($) | C13: =C11/('Your Inputs'!C8*'Your Inputs'!C9)*1000 -> 4.5 | D13: =D11/('Your Inputs'!C8*'Your Inputs'!C9)*1000 -> 2.625 | E13: =E11/('Your Inputs'!C8*'Your Inputs'!C9)*1000 -> 0.195 | F13: =F11/('Your Inputs'!C8*'Your Inputs'!C9)*1000 -> 0.55
B14: Adjusted annual (excl. $0 providers) | C14: =IF(C11>0,C11,9999999) -> 16425 | D14: =IF(D11>0,D11,9999999) -> 9581.25 | E14: =IF(E11>0,E11,9999999) -> 711.75 | F14: =IF(F11>0,F11,9999999) -> 2007.5
B15: Smart Routing Scenario
B16: Route 60% to cheapest provider, 40% to 2nd cheapest (across all 4)
B17: Blended annual cost ($) | C17: =0.6*SMALL(C14:F14,1)+0.4*SMALL(C14:F14,2) -> 1230.05
B18: Monthly blended cost ($) | C18: =C17/12 -> 102.50417
B19: Savings vs. average single provider | C19: =IFERROR(1-C17/AVERAGEIF(C11:F11,">0"),0) -> 0.82871665

Sheet Self-Hosted GPU
B2: Self-Hosted GPU Cost Analysis
B4: Cost Component | C4: Annual Cost ($) | D4: Formula / Notes
B5: GPU compute cost | C5: ='Your Inputs'!C34*'Your Inputs'!C35*'Your Inputs'!C37*'Your Inputs'!C9 -> 21900 | D5: $/hr × GPUs × hrs/day × days/yr
B6: ML engineer cost (allocated) | C6: ='Your Inputs'!C39*'Your Inputs'!C40/100 -> 45000 | D6: Salary × % time on project
B7: Setup cost (amortized over 3 years) | C7: ='Your Inputs'!C41/3 -> 5000 | D7: One-time cost / 3 years
B8: Software licenses (est.) | C8: 2000 | D8: Inference framework, monitoring, etc.
B9: Data transfer / networking (est.) | C9: 3000 | D9: Egress, VPN, load balancing
B11: TOTAL ANNUAL COST | C11: =SUM(C5:C9) -> 76900
B12: Monthly cost | C12: =C11/12 -> 6408.3333
B14: Capacity Analysis
B15: Max tokens/day (at stated throughput) | C15: ='Your Inputs'!C38*'Your Inputs'!C35*3600*'Your Inputs'!C37*'Your Inputs'!C36/100 -> 139104000 | D15: tok/s × GPUs × 3600 × hrs/day × utilization%
B16: Your daily token need | C16: ='Your Inputs'!C14 -> 7000000
B17: Capacity headroom | C17: =C15/C16-1 -> 18.872 | D17: Should be > 0%. If negative, add more GPUs.
B18: Effective cost per 1M tokens | C18: =C11/('Your Inputs'!C14*'Your Inputs'!C9/1000000) -> 30.097847

Sheet Local - Edge
B2: Local / Edge Deployment Cost Analysis
B4: Cost Component | C4: Annual Cost ($) | D4: Formula / Notes
B5: Hardware (amortized) | C5: ='Your Inputs'!C45*'Your Inputs'!C46/'Your Inputs'!C49 -> 666.33333 | D5: Purchase cost × devices / lifetime years
B6: Electricity | C6: ='Your Inputs'!C47*'Your Inputs'!C46*'Your Inputs'!C50/1000*'Your Inputs'!C9*'Your Inputs'!C48 -> 604.44 | D6: Watts × devices × hrs/day / 1000 × days/yr × $/kWh
B7: IT support / maintenance | C7: ='Your Inputs'!C52 -> 5000 | D7: Annual support cost
B8: Software / licensing (est.) | C8: 500 | D8: Ollama, llama.cpp, monitoring tools
B10: TOTAL ANNUAL COST | C10: =SUM(C5:C8) -> 6770.7733
B11: Monthly cost | C11: =C10/12 -> 564.23111
B13: Capacity Analysis
B14: Max tokens/day (at stated throughput) | C14: ='Your Inputs'!C51*'Your Inputs'!C46*3600*'Your Inputs'!C50 -> 8640000
B15: Your daily token need | C15: ='Your Inputs'!C14 -> 7000000
B16: Capacity headroom | C16: =C14/C15-1 -> 0.23428571
B17: Effective cost per 1M tokens | C17: =C10/('Your Inputs'!C14*'Your Inputs'!C9/1000000) -> 2.6500091

Sheet Comparison
B2: Side-by-Side Comparison
B3: All costs annualized. API (Best Single) = cheapest among your 4 selected providers.
B5: Metric | C5: API (Best Single) | D5: API (Smart Routing) | E5: Self-Hosted GPU | F5: Local / Edge
B6: Annual total cost ($) | C6: =MIN('API Costs'!C14,'API Costs'!D14,'API Costs'!E14,'API Costs'!F14) -> 711.75 | D6: ='API Costs'!C17 -> 1230.05 | E6: ='Self-Hosted GPU'!C11 -> 76900 | F6: ='Local - Edge'!C10 -> 6770.7733
B7: Monthly cost ($) | C7: =C6/12 -> 59.3125 | D7: =D6/12 -> 102.50417 | E7: ='Self-Hosted GPU'!C12 -> 6408.3333 | F7: ='Local - Edge'!C11 -> 564.23111
B8: Cost per 1M tokens ($) | C8: =C6/('Your Inputs'!C14*'Your Inputs'!C9/1000000) -> 0.27857143 | D8: =D6/('Your Inputs'!C14*'Your Inputs'!C9/1000000) -> 0.48142857 | E8: ='Self-Hosted GPU'!C18 -> 30.097847 | F8: ='Local - Edge'!C17 -> 2.6500091
B9: Data leaves your network? | C9: Yes | D9: Yes | E9: No (your cloud VPC) | F9: No (fully local)
B10: ML team required? | C10: No | D10: No | E10: Yes | F10: Minimal
B11: Scales with volume? | C11: Linear cost increase | D11: Linear cost increase | E11: Fixed cost (to capacity) | F11: Fixed cost (to capacity)
B12: EU AI Act compliant? | C12: Depends on vendor DPA | D12: Depends on vendor DPA | E12: Full control | F12: Full control
B13: Time to deploy | C13: Days | D13: Days | E13: Weeks | F13: Days to weeks
B15: LOWEST COST OPTION | C15: =IF(MIN(C6,D6,E6,F6)=C6,"API (Best Single)",IF(MIN(C6,D6,E6,F6)=D6,"API (Smart Routing)",IF(MIN(C6,D6,E6,F6)=E6,"Self-Hosted GPU","Local / Edge"))) -> API (Best Single)
B16: Annual savings vs. most expensive | C16: =MAX(C6,D6,E6,F6)-MIN(C6,D6,E6,F6) -> 76188.25
B17: Savings percentage | C17: =1-MIN(C6,D6,E6,F6)/MAX(C6,D6,E6,F6) -> 0.99074447
B19: Best single API provider | C19: =IF(MIN('API Costs'!C14,'API Costs'!D14,'API Costs'!E14,'API Costs'!F14)='API Costs'!C11,'API Costs'!C4,IF(MIN('API Costs'!C14,'API Costs'!D14,'API Costs'!E14,'API Costs'!F14)='API Costs'!D11,'API Costs'!D4,IF(MIN('API Costs'!C14,'API Costs'!D14,'API Costs'!E14,'API Costs'!F14)='API Costs'!E11,'API Costs'!E4,'API Costs'!F4))) -> Gemini 2.5 Flash
B21: Break-Even Analysis
B22: Self-hosted break-even vs. best API (months) | C22: =IF(E6<C6,('Your Inputs'!C41)/((C6-E6)/12),"API is cheaper") -> API is cheaper | D22: Months until self-hosted investment pays off
B24: By Julien Simon | AI Operating Partner, Fortino Capital

Sheet Model Library
A1: Model Name | B1: Provider | C1: Input $/M tok | D1: Output $/M tok | E1: Notes
A2: GPT-5.2 Pro | B2: OpenAI | C2: 21 | D2: 168 | E2: Reasoning model, 2× standard cost tier
A3: GPT-5.2 | B3: OpenAI | C3: 1.75 | D3: 14 | E3: Latest flagship, Dec 2025
A4: GPT-5.1 | B4: OpenAI | C4: 1.25 | D4: 10 | E4: Coding-optimized variant
A5: GPT-5 | B5: OpenAI | C5: 1.25 | D5: 10 | E5: Released Aug 2025, 400K context
A6: GPT-5 Mini | B6: OpenAI | C6: 0.25 | D6: 2 | E6: Efficient mid-tier, great value
A7: GPT-5 Nano | B7: OpenAI | C7: 0.05 | D7: 0.4 | E7: Cheapest OpenAI option
A8: GPT-4o | B8: OpenAI | C8: 2.5 | D8: 10 | E8: Multimodal with vision, 128K context
A9: GPT-4o Mini | B9: OpenAI | C9: 0.15 | D9: 0.6 | E9: Budget multimodal, 128K context
A10: o1 | B10: OpenAI | C10: 15 | D10: 60 | E10: Advanced reasoning, high-cost
A11: o3 | B11: OpenAI | C11: 10 | D11: 40 | E11: Next-gen reasoning
A12: o4-mini | B12: OpenAI | C12: 1.1 | D12: 4.4 | E12: Affordable reasoning model
A13: Claude Opus 4.6 | B13: Anthropic | C13: 5 | D13: 25 | E13: Most capable Anthropic model
... A28: DeepSeek V3.2 | B28: DeepSeek | C28: 0.25 | D28: 0.38 | E28: Cost-effective API, strong coding/math performance
A29: Arcee Trinity Large | B29: Arcee AI | C29: N/A (self-hosted) | D29: N/A (self-hosted) | E29: Open-weights 420B AFMoE (13B active). Self-hosted only.
A30: Arcee Trinity Mini | B30: Arcee AI | C30: N/A (self-hosted) | D30: N/A (self-hosted) | E30: Open-weights 17B AFMoE (4B active). Self-hosted only.
A32: Pricing as of February 2026. Sources: openai.com/api/pricing, platform.claude.com/docs, ai.google.dev/gemini-api/docs/pricing
